<robot>
  <joint name="tilt" type="prismatic">
    <parent link="axis"/>
    <child link="body"/>
    <origin xyz="0 0 0" rpy="0.0, 0.0, 0.0"/>
    <axis xyz="0 1 0"/>
    <limit upper="0" lower="-0.5" effort="10" velocity="10"/>
  </joint>
  <link name="axis">
    <inertial>
      <mass value="1"/>
      <interia ixx="100" ixy="0" ixz="0" iyy="100" iyz="0" izz="0"/>
      <origin/>
    </inertial>
    <visual>
      <origin xyz="0 0 0" rpy="0.0, 0.0, 0.0"/>
      <geometry>
        <cylinder radius="0.01" length="0.5"/>
      </geometry>
      <material name="grey">
        <color rgba="0.2 0.2 0.2 1"/>
      </material>
    </visual>
    <collision>
      <origin xyz="0 0 0" rpy="0.0, 0.0, 0.0"/>
      <geometry>
        <cylinder radius="0.01" length="0.5"/>
      </geometry>
      <contact_coefficients mu="0" kp="1000.0" kd="1.0"/>
    </collision>
  </link>
  <joint name="tilt" type="prismatic">
    <parent link="axis"/>
    <child link="body"/>
    <origin xyz="0 0 0" rpy="1.57, 0.0, 1.57"/>
    <axis xyz="0 1 0"/>
    <limit upper="0" lower="-0.5" effort="10" velocity="10"/>
  </joint>
  <link name="axis">
    <inertial>
      <mass value="1"/>
      <interia ixx="100" ixy="0" ixz="0" iyy="100" iyz="0" izz="0"/>
      <origin/>
    </inertial>
    <visual>
      <origin xyz="0 0 0" rpy="1.57, 0.0, 1.57"/>
      <geometry>
        <cylinder radius="0.01" length="0.5"/>
      </geometry>
      <material name="grey">
        <color rgba="0.2 0.2 0.2 1"/>
      </material>
    </visual>
    <collision>
      <origin xyz="0 0 0" rpy="1.57, 0.0, 1.57"/>
      <geometry>
        <cylinder radius="0.01" length="0.5"/>
      </geometry>
      <contact_coefficients mu="0" kp="1000.0" kd="1.0"/>
    </collision>
  </link>
  <joint name="tilt" type="prismatic">
    <parent link="axis"/>
    <child link="body"/>
    <origin xyz="0 0 0" rpy="1.57, 0.0, 1.57"/>
    <axis xyz="0 1 0"/>
    <limit upper="0" lower="-0.5" effort="10" velocity="10"/>
  </joint>
  <link name="axis">
    <inertial>
      <mass value="1"/>
      <interia ixx="100" ixy="0" ixz="0" iyy="100" iyz="0" izz="0"/>
      <origin/>
    </inertial>
    <visual>
      <origin xyz="0 0 0" rpy="1.57, 0.0, 1.57"/>
      <geometry>
        <cylinder radius="0.01" length="0.5"/>
      </geometry>
      <material name="grey">
        <color rgba="0.2 0.2 0.2 1"/>
      </material>
    </visual>
    <collision>
      <origin xyz="0 0 0" rpy="1.57, 0.0, 1.57"/>
      <geometry>
        <cylinder radius="0.01" length="0.5"/>
      </geometry>
      <contact_coefficients mu="0" kp="1000.0" kd="1.0"/>
    </collision>
  </link>
</robot>
