<robot name="my_robot">
  <link name="base_link">
    <visual>
      <origin xyz="0 0 0.5" rpy="0 0 0"/>
      <geometry>
        <cylinder radius="0.3" length="1"/>
      </geometry>
      <material name="blue">
        <color rgba="0.5 0.5 0.5 1"/>
      </material>
    </visual>
    <collision>
      <origin xyz="0 0 0.5" rpy="0 0 0"/>
      <geometry>
        <cylinder radius="0.3" length="1"/>
      </geometry>
      <contact_coefficients mu="0" kp="1000.0" kd="1.0"/>
    </collision>
  </link>
  <joint name="joint_base_1" type="prismatic">
    <parent link="base_link"/>
    <child link="link_1"/>
    <origin xyz="0.0 0.0 2.0" rpy="0.0 -0.0 0.0"/>
    <axis xyz="0 0 1"/>
    <limit upper="0" lower="-1" effort="10" velocity="10"/>
  </joint>
  <link name="link_1">
    <visual>
      <origin xyz="0 0 -0.5" rpy="0 0 0"/>
      <geometry>
        <cylinder radius="0.1" length="1"/>
      </geometry>
      <material name="red">
        <color rgba="1 0.5 0 1"/>
      </material>
    </visual>
    <collision>
      <origin xyz="0 0 -0.5" rpy="0 0 0"/>
      <geometry>
        <cylinder radius="0.1" length="1"/>
      </geometry>
      <contact_coefficients mu="0" kp="1000.0" kd="1.0"/>
    </collision>
  </link>
  <joint name="joint_1_2" type="prismatic">
    <parent link="link_1"/>
    <child link="link_2"/>
    <origin xyz="0.0 -0.9999996829318346 0.0007963267107332633" rpy="0.7853980048633404 -1.5696701507009851 0.7853980048633404"/>
    <axis xyz="0 0 1"/>
    <limit upper="0" lower="-1" effort="10" velocity="10"/>
  </joint>
  <link name="link_2">
    <visual>
      <origin xyz="0 0 -0.5" rpy="0 0 0"/>
      <geometry>
        <cylinder radius="0.1" length="1"/>
      </geometry>
      <material name="green">
        <color rgba="1 0.5 0 1"/>
      </material>
    </visual>
    <collision>
      <origin xyz="0 0 -0.5" rpy="0 0 0"/>
      <geometry>
        <cylinder radius="0.1" length="1"/>
      </geometry>
      <contact_coefficients mu="0" kp="1000.0" kd="1.0"/>
    </collision>
  </link>
  <joint name="joint_2_3" type="prismatic">
    <parent link="link_2"/>
    <child link="link_3"/>
    <origin xyz="0.0 -0.9999996829318346 0.0007963267107332633" rpy="0.7853980048633404 -1.5696701507009851 0.7853980048633404"/>
    <axis xyz="0 0 1"/>
    <limit upper="0" lower="-1" effort="10" velocity="10"/>
  </joint>
  <link name="link_3">
    <visual>
      <origin xyz="0 0 -0.5" rpy="0 0 0"/>
      <geometry>
        <cylinder radius="0.1" length="1"/>
      </geometry>
      <material name="red">
        <color rgba="1 0.5 0 1"/>
      </material>
    </visual>
    <collision>
      <origin xyz="0 0 -0.5" rpy="0 0 0"/>
      <geometry>
        <cylinder radius="0.1" length="1"/>
      </geometry>
      <contact_coefficients mu="0" kp="1000.0" kd="1.0"/>
    </collision>
  </link>
  <joint name="joint_3_tool" type="fixed">
    <parent link="link_3"/>
    <child link="tool"/>
    <origin xyz="0 0 0.1" rpy="0 0 0"/>
    <axis xyz="0 0 1"/>
    <limit upper="0" lower="-0.2" effort="10" velocity="10"/>
  </joint>
  <link name="tool">
    <visual>
      <origin xyz="0 0 0" rpy="0 0 0"/>
      <geometry>
        <cylinder radius="0.05" length="0.2"/>
      </geometry>
      <material name="blue">
        <color rgba="1 0.5 0 1"/>
      </material>
    </visual>
    <collision>
      <origin xyz="0 0 0.1" rpy="0 0 0"/>
      <geometry>
        <cylinder radius="0.05" length="0.2"/>
      </geometry>
      <contact_coefficients mu="0" kp="1000.0" kd="1.0"/>
    </collision>
  </link>
</robot>
